In main
[[34m2024-04-18 19:32:36[0m] Experiment directory created at results/002-256-emonet-OneDirection
Traceback (most recent call last):
  File "/scratch/sl10152/cognitiveGANs/train.py", line 248, in <module>
    main(args)
  File "/scratch/sl10152/cognitiveGANs/train.py", line 114, in main
    generator = get_generator(args.generator_pixels, dim_z)
                ^^^^^^^^^^^^^^^^^^^^^^^^^^^^^^^^^^^^^^^^^^^
  File "/scratch/sl10152/cognitiveGANs/models/biggan.py", line 254, in get_generator
    G.load_state_dict(torch.load(s))
                      ^^^^^^^^^^^^^
  File "/ext3/miniconda3/lib/python3.11/site-packages/torch/serialization.py", line 998, in load
    with _open_file_like(f, 'rb') as opened_file:
         ^^^^^^^^^^^^^^^^^^^^^^^^
  File "/ext3/miniconda3/lib/python3.11/site-packages/torch/serialization.py", line 445, in _open_file_like
    return _open_file(name_or_buffer, mode)
           ^^^^^^^^^^^^^^^^^^^^^^^^^^^^^^^^
  File "/ext3/miniconda3/lib/python3.11/site-packages/torch/serialization.py", line 426, in __init__
    super().__init__(open(name, mode))
                     ^^^^^^^^^^^^^^^^
FileNotFoundError: [Errno 2] No such file or directory: '/scratch/sl10152/cognitiveGANs/models/biggan-256.pth'
[2024-04-18 19:32:51,629] torch.distributed.elastic.multiprocessing.api: [ERROR] failed (exitcode: 1) local_rank: 0 (pid: 1073487) of binary: /ext3/miniconda3/bin/python
Traceback (most recent call last):
  File "/ext3/miniconda3/bin/torchrun", line 8, in <module>
    sys.exit(main())
             ^^^^^^
  File "/ext3/miniconda3/lib/python3.11/site-packages/torch/distributed/elastic/multiprocessing/errors/__init__.py", line 347, in wrapper
    return f(*args, **kwargs)
           ^^^^^^^^^^^^^^^^^^
  File "/ext3/miniconda3/lib/python3.11/site-packages/torch/distributed/run.py", line 812, in main
    run(args)
  File "/ext3/miniconda3/lib/python3.11/site-packages/torch/distributed/run.py", line 803, in run
    elastic_launch(
  File "/ext3/miniconda3/lib/python3.11/site-packages/torch/distributed/launcher/api.py", line 135, in __call__
    return launch_agent(self._config, self._entrypoint, list(args))
           ^^^^^^^^^^^^^^^^^^^^^^^^^^^^^^^^^^^^^^^^^^^^^^^^^^^^^^^^
  File "/ext3/miniconda3/lib/python3.11/site-packages/torch/distributed/launcher/api.py", line 268, in launch_agent
    raise ChildFailedError(
torch.distributed.elastic.multiprocessing.errors.ChildFailedError: 
============================================================
train.py FAILED
------------------------------------------------------------
Failures:
  <NO_OTHER_FAILURES>
------------------------------------------------------------
Root Cause (first observed failure):
[0]:
  time      : 2024-04-18_19:32:51
  host      : gr007.hpc.nyu.edu
  rank      : 0 (local_rank: 0)
  exitcode  : 1 (pid: 1073487)
  error_file: <N/A>
  traceback : To enable traceback see: https://pytorch.org/docs/stable/elastic/errors.html
============================================================
